2022-05-04 21:54:02.469 wdl.w:hworld_workflow NOTICE workflow start :: name: "hworld_workflow", source: "/home/michelle_scribner/wm_training/wdl/workflows/wf_hworld.wdl", line: 6, column: 1, dir: "/home/michelle_scribner/wm_training/20220504_215402_hworld_workflow"
2022-05-04 21:54:02.472 wdl.w:hworld_workflow NOTICE miniwdl :: version: "v1.5.1", uname: "Linux scribner-dev-vm 5.13.0-1024-gcp #29~20.04.1-Ubuntu SMP Thu Apr 14 23:15:00 UTC 2022 x86_64"
2022-05-04 21:54:02.487 wdl.w:hworld_workflow NOTICE ready :: job: "call-hworld_task", callee: "hworld_task"
2022-05-04 21:54:02.488 wdl.w:hworld_workflow.t:call-hworld_task NOTICE task setup :: name: "hworld_task", source: "../tasks/task_hworld.wdl", line: 3, column: 1, dir: "/home/michelle_scribner/wm_training/20220504_215402_hworld_workflow/call-hworld_task", thread: 140685613201152
2022-05-04 21:54:02.633 wdl.w:hworld_workflow.t:call-hworld_task ERROR task hworld_task (../tasks/task_hworld.wdl Ln 3 Col 1) failed :: dir: "/home/michelle_scribner/wm_training/20220504_215402_hworld_workflow/call-hworld_task", error: "DockerException", message: "Error while fetching server API version: ('Connection aborted.', PermissionError(13, 'Permission denied'))", traceback: ["Traceback (most recent call last):", "  File \"/usr/lib/python3/dist-packages/urllib3/connectionpool.py\", line 665, in urlopen", "    httplib_response = self._make_request(", "  File \"/usr/lib/python3/dist-packages/urllib3/connectionpool.py\", line 387, in _make_request", "    conn.request(method, url, **httplib_request_kw)", "  File \"/usr/lib/python3.8/http/client.py\", line 1256, in request", "    self._send_request(method, url, body, headers, encode_chunked)", "  File \"/usr/lib/python3.8/http/client.py\", line 1302, in _send_request", "    self.endheaders(body, encode_chunked=encode_chunked)", "  File \"/usr/lib/python3.8/http/client.py\", line 1251, in endheaders", "    self._send_output(message_body, encode_chunked=encode_chunked)", "  File \"/usr/lib/python3.8/http/client.py\", line 1011, in _send_output", "    self.send(msg)", "  File \"/usr/lib/python3.8/http/client.py\", line 951, in send", "    self.connect()", "  File \"/usr/local/lib/python3.8/dist-packages/docker/transport/unixconn.py\", line 30, in connect", "    sock.connect(self.unix_socket)", "PermissionError: [Errno 13] Permission denied", "", "During handling of the above exception, another exception occurred:", "", "Traceback (most recent call last):", "  File \"/usr/lib/python3/dist-packages/requests/adapters.py\", line 439, in send", "    resp = conn.urlopen(", "  File \"/usr/lib/python3/dist-packages/urllib3/connectionpool.py\", line 719, in urlopen", "    retries = retries.increment(", "  File \"/usr/lib/python3/dist-packages/urllib3/util/retry.py\", line 400, in increment", "    raise six.reraise(type(error), error, _stacktrace)", "  File \"/usr/lib/python3/dist-packages/six.py\", line 702, in reraise", "    raise value.with_traceback(tb)", "  File \"/usr/lib/python3/dist-packages/urllib3/connectionpool.py\", line 665, in urlopen", "    httplib_response = self._make_request(", "  File \"/usr/lib/python3/dist-packages/urllib3/connectionpool.py\", line 387, in _make_request", "    conn.request(method, url, **httplib_request_kw)", "  File \"/usr/lib/python3.8/http/client.py\", line 1256, in request", "    self._send_request(method, url, body, headers, encode_chunked)", "  File \"/usr/lib/python3.8/http/client.py\", line 1302, in _send_request", "    self.endheaders(body, encode_chunked=encode_chunked)", "  File \"/usr/lib/python3.8/http/client.py\", line 1251, in endheaders", "    self._send_output(message_body, encode_chunked=encode_chunked)", "  File \"/usr/lib/python3.8/http/client.py\", line 1011, in _send_output", "    self.send(msg)", "  File \"/usr/lib/python3.8/http/client.py\", line 951, in send", "    self.connect()", "  File \"/usr/local/lib/python3.8/dist-packages/docker/transport/unixconn.py\", line 30, in connect", "    sock.connect(self.unix_socket)", "urllib3.exceptions.ProtocolError: ('Connection aborted.', PermissionError(13, 'Permission denied'))", "", "During handling of the above exception, another exception occurred:", "", "Traceback (most recent call last):", "  File \"/usr/local/lib/python3.8/dist-packages/docker/api/client.py\", line 214, in _retrieve_server_version", "    return self.version(api_version=False)[\"ApiVersion\"]", "  File \"/usr/local/lib/python3.8/dist-packages/docker/api/daemon.py\", line 181, in version", "    return self._result(self._get(url), json=True)", "  File \"/usr/local/lib/python3.8/dist-packages/docker/utils/decorators.py\", line 46, in inner", "    return f(self, *args, **kwargs)", "  File \"/usr/local/lib/python3.8/dist-packages/docker/api/client.py\", line 237, in _get", "    return self.get(url, **self._set_request_timeout(kwargs))", "  File \"/usr/lib/python3/dist-packages/requests/sessions.py\", line 546, in get", "    return self.request('GET', url, **kwargs)", "  File \"/usr/lib/python3/dist-packages/requests/sessions.py\", line 533, in request", "    resp = self.send(prep, **send_kwargs)", "  File \"/usr/lib/python3/dist-packages/requests/sessions.py\", line 646, in send", "    r = adapter.send(request, **kwargs)", "  File \"/usr/lib/python3/dist-packages/requests/adapters.py\", line 498, in send", "    raise ConnectionError(err, request=request)", "requests.exceptions.ConnectionError: ('Connection aborted.', PermissionError(13, 'Permission denied'))", "", "During handling of the above exception, another exception occurred:", "", "Traceback (most recent call last):", "  File \"/usr/local/lib/python3.8/dist-packages/WDL/runtime/task.py\", line 166, in run_local_task", "    container = new_task_container(cfg, logger, run_id, run_dir)", "  File \"/usr/local/lib/python3.8/dist-packages/WDL/runtime/task_container.py\", line 379, in new", "    backend_cls.global_init(cfg, logger)", "  File \"/usr/local/lib/python3.8/dist-packages/WDL/runtime/backend/docker_swarm.py\", line 40, in global_init", "    client = docker.from_env(version=\"auto\")", "  File \"/usr/local/lib/python3.8/dist-packages/docker/client.py\", line 96, in from_env", "    return cls(", "  File \"/usr/local/lib/python3.8/dist-packages/docker/client.py\", line 45, in __init__", "    self.api = APIClient(*args, **kwargs)", "  File \"/usr/local/lib/python3.8/dist-packages/docker/api/client.py\", line 197, in __init__", "    self._version = self._retrieve_server_version()", "  File \"/usr/local/lib/python3.8/dist-packages/docker/api/client.py\", line 221, in _retrieve_server_version", "    raise DockerException(", "docker.errors.DockerException: Error while fetching server API version: ('Connection aborted.', PermissionError(13, 'Permission denied'))"]
2022-05-04 21:54:02.636 wdl.w:hworld_workflow ERROR call failure propagating :: from: "call-hworld_task", dir: "/home/michelle_scribner/wm_training/20220504_215402_hworld_workflow"
2022-05-04 21:54:02.637 wdl.w:hworld_workflow NOTICE aborting workflow
